Workbook
Name Lista_Documentos: DOCUMENTOS!$B$12:$B$1108
Name Lista_Proveedores: CLIENTES!$B$12:$B$403
Name SegmentaciónDeDatos_ESTADO_DE_PAGO: #N/A
Name SegmentaciónDeDatos_INICIAL: #N/A

Sheet CLIENTES
C4: =SUBTOTAL(3,C12:C2351) -> 392
B11: RUT | C11: CLIENTE | D11: CELULAR | E11: PERSONA CLAVE | F11: INICIAL
B12: 12219231-8 | C12: WILSON ELEODORO MERINO ROJAS | F12: =LEFT(C12) -> W
B13: 14485102-1 | C13: LORENA CARMEN OTAROLA SOTO | F13: =LEFT(C13) -> L
B14: 18218891-3 | C14: FERNANDO ESTEBAN DIAZ SANQUINETTI | F14: =LEFT(C14) -> F
B15: 92475000-6 | C15: KAUFMANN SA VEHICULOS MOTORIZADOS | F15: =LEFT(C15) -> K
B16: 78320430-4 | C16: AUTOMOTRIZ NICOLAS LTDA. | F16: =LEFT(C16) -> A
B17: 77578446-6 | C17: JOYERIA Y RELOJERIA KARIME DAU SPA | F17: =LEFT(C17) -> J
B18: 78747740-2 | C18: SERVICIOS INDUSTRIALES WARNER SPA | F18: =LEFT(C18) -> S
B19: 78055616-1 | C19: SERVICIOS INTEGRALES LA RIVERA SPA | F19: =LEFT(C19) -> S
B20: 76574783-K | C20: LC GROUP INTERNATIONAL SPA | F20: =LEFT(C20) -> L
B21: 77520219-K | C21: AILUV SPA | F21: =LEFT(C21) -> A
B22: 76410595-8 | C22: CROSAN SPA | F22: =LEFT(C22) -> C
B23: 77978769-9 | C23: PALMON SPA | F23: =LEFT(C23) -> P
... B49: 7307203-4 | C49: CECILIA MARCELA MATULIC CARMONA | F49: =LEFT(C49) -> C
B50: 76346498-9 | C50: CONSTRUCTORA CARLOS ALBERTO ANDRES ALBISTUR REYES E.I.R.L. | D50: +569 6654 2647 | E50: ALEJANDRO MORALES | F50: =LEFT(C50) -> C
B51: 76646820-9 | C51: SERVICIOS,TRANSPORTE Y ARRIENDO DE MAQUINARIAS LIMITADA | F51: =LEFT(C51) -> S
B52: 77490658-4 | C52: SA INVERSIONES SPA | F52: =LEFT(C52) -> S
B53: 76478614-9 | C53: INGENIERIA C Y G LIMITADA | F53: =LEFT(C53) -> I
B54: 77313060-4 | C54: COMERCIAL SERPAN SPA | F54: =LEFT(C54) -> C
B55: 18403693-2 | C55: CAROLINA ANDREA BARRERA QUINELEN | F55: =LEFT(C55) -> C
B56: 76451155-7 | C56: IMPORTADORA Y COMERCIAL JOMIAL LIMITADA | F56: =LEFT(C56) -> I
B57: 77471172-4 | C57: AMAZONAS SPA | F57: =LEFT(C57) -> A
B58: 77902909-3 | C58: SERVICIOS DE INGENIERIA MIRAITEK TI SPA | F58: =LEFT(C58) -> S
B59: 99598680-9 | C59: GRAN CASINO DE COPIAPO S.A. | F59: =LEFT(C59) -> G
B60: 77524646-4 | C60: SOCIEDAD COMERCIAL MASKOLANDIA Y COMPAÑIA LIMITADA | F60: =LEFT(C60) -> S
B61: 77183342-K | C61: TRANSPORTE Y SERVICIO ALEXIS ALEJANDRO SARRIA ALDEA EMPRESA INDIVIDUAL | F61: =LEFT(C61) -> T
B62: 76258990-7 | C62: ON STREET S.A. | F62: =LEFT(C62) -> O
... B85: 96774300-3 | C85: ENORCHILE S.A. | F85: =LEFT(C85) -> E
B86: 76250422-7 | C86: CENTRO DE RECICLAJE DEL NORTE LIMITADA | D86: +569 9948 2539 | E86: CAROLINA | F86: =LEFT(C86) -> C
B87: 77028674-3 | C87: SOCIEDAD COMERCIAL HERMANOS GODOY ARAYA SPA | F87: =LEFT(C87) -> S
B88: 9051431-8 | C88: RAMON ANGEL RIQUELME OLIVARES | F88: =LEFT(C88) -> R
B89: 78808300-9 | C89: EDWIN HOLVOET Y COMPANIA LIMITADA | D89: +569 6468 1946 | E89: FELIPE felipeholvoet@holvoet.cl | F89: =LEFT(C89) -> E
B90: 76096151-5 | C90: JP ELECTRONIC SOCIEDAD ANONIMA | F90: =LEFT(C90) -> J
B91: 76549850-3 | C91: COMERCIAL ATACAMA TRUCKS PARTS LIMITADA | F91: =LEFT(C91) -> C
B92: 77067531-6 | C92: VIDRIERIA Y TRANSPORTES ROX SPA | F92: =LEFT(C92) -> V
B93: 76523982-6 | C93: SUDAMERICANA DE GESTION EMPRESARIAL LIMITADA | F93: =LEFT(C93) -> S
B94: 77225118-1 | C94: JERALDO TOPOGRAFÃA SUBTERRÃNEA Y GEODÃ‰SICA SPA | F94: =LEFT(C94) -> J
B95: 77885825-8 | C95: SERVICIOS ARDIRAB SPA | F95: =LEFT(C95) -> S
B96: 77002348-3 | C96: SERVICIOS INDUSTRIALES ROBERTO FERNANDEZ SPA | F96: =LEFT(C96) -> S
...

Sheet DOCUMENTOS
B11: NRO DOC | C11: FECHA DE EMISIÓN | D11: RUT | E11: CLIENTE | F11: IMPORTE A COBRAR | G11: TIPO | H11: DÍAS DE CRÉDITO | I11: CONDICIÓN DE PAGO | J11: FECHA DE VENCIMIENTO | K11: DÍAS POR VENCER | L11: ESTADO DE PAGO | M11: IMPORTE ABONADO | N11: IMPORTE POR COBRAR | O11: FECHA DE ULTIMO ABONO
B12: 884 | C12: 45661 | D12: 77361091-6 | E12: =IFERROR(VLOOKUP(D12,CLIENTES!$B$12:$G$2602,2,FALSE),"") -> OSSAVAL SPA | F12: 83300 | G12: PUBLICIDAD | H12: 0 | I12: =IF(H12="","",IF(H12=0,"Contado","Crédito")) -> Contado | J12: =IF(I12="","",C12+H12) -> 45661 | K12: =IFERROR(IF(B12="","",IF(N12=0,0,J12-TODAY())),"") -> 0 | L12: =IF(I12="","",IF(N12=0,"Pagado",IF(K12<0,"Vencido","No vencido"))) -> Pagado | M12: =SUMIFS(Tabla_Pagos[IMPORTE ABONADO],Tabla_Pagos[FECHA DE ABONO],">0",Tabla_Pagos[NRO DOC],B12) -> 83300 | N12: =F12-M12 -> 0 | O12: {=MAX(IF((Tabla_Pagos[NRO DOC]=B12)*(Tabla_Pagos[IMPORTE ABONADO]>0),Tabla_Pagos[FECHA DE ABONO]))} -> 45661
B13: 885 | C13: 45661 | D13: 77137806-4 | E13: =IFERROR(VLOOKUP(D13,CLIENTES!$B$12:$G$2602,2,FALSE),"") -> CONSTRUCTORA GARY LIMITADA | F13: 163030 | G13: PUBLICIDAD | H13: 0 | I13: =IF(H13="","",IF(H13=0,"Contado","Crédito")) -> Contado | J13: =IF(I13="","",C13+H13) -> 45661 | K13: =IFERROR(IF(B13="","",IF(N13=0,0,J13-TODAY())),"") -> 0 | L13: =IF(I13="","",IF(N13=0,"Pagado",IF(K13<0,"Vencido","No vencido"))) -> Pagado | M13: =SUMIFS(Tabla_Pagos[IMPORTE ABONADO],Tabla_Pagos[FECHA DE ABONO],">0",Tabla_Pagos[NRO DOC],B13) -> 163030 | N13: =F13-M13 -> 0 | O13: {=MAX(IF((Tabla_Pagos[NRO DOC]=B13)*(Tabla_Pagos[IMPORTE ABONADO]>0),Tabla_Pagos[FECHA DE ABONO]))} -> 45661
B14: 886 | C14: 45661 | D14: 77758444-8 | E14: =IFERROR(VLOOKUP(D14,CLIENTES!$B$12:$G$2602,2,FALSE),"") -> TRANSPORTE DOBLE C SPA | F14: 166600 | G14: PUBLICIDAD | H14: 0 | I14: =IF(H14="","",IF(H14=0,"Contado","Crédito")) -> Contado | J14: =IF(I14="","",C14+H14) -> 45661 | K14: =IFERROR(IF(B14="","",IF(N14=0,0,J14-TODAY())),"") -> 0 | L14: =IF(I14="","",IF(N14=0,"Pagado",IF(K14<0,"Vencido","No vencido"))) -> Pagado | M14: =SUMIFS(Tabla_Pagos[IMPORTE ABONADO],Tabla_Pagos[FECHA DE ABONO],">0",Tabla_Pagos[NRO DOC],B14) -> 166600 | N14: =F14-M14 -> 0 | O14: {=MAX(IF((Tabla_Pagos[NRO DOC]=B14)*(Tabla_Pagos[IMPORTE ABONADO]>0),Tabla_Pagos[FECHA DE ABONO]))} -> 45661
B15: 887 | C15: 45663 | D15: 77907297-5 | E15: =IFERROR(VLOOKUP(D15,CLIENTES!$B$12:$G$2602,2,FALSE),"") -> LEYARZ SPA | F15: 142800 | G15: PUBLICIDAD | H15: 0 | I15: =IF(H15="","",IF(H15=0,"Contado","Crédito")) -> Contado | J15: =IF(I15="","",C15+H15) -> 45663 | K15: =IFERROR(IF(B15="","",IF(N15=0,0,J15-TODAY())),"") -> 0 | L15: =IF(I15="","",IF(N15=0,"Pagado",IF(K15<0,"Vencido","No vencido"))) -> Pagado | M15: =SUMIFS(Tabla_Pagos[IMPORTE ABONADO],Tabla_Pagos[FECHA DE ABONO],">0",Tabla_Pagos[NRO DOC],B15) -> 142800 | N15: =F15-M15 -> 0 | O15: {=MAX(IF((Tabla_Pagos[NRO DOC]=B15)*(Tabla_Pagos[IMPORTE ABONADO]>0),Tabla_Pagos[FECHA DE ABONO]))} -> 45663
B16: 888 | C16: 45666 | D16: 76478614-9 | E16: =IFERROR(VLOOKUP(D16,CLIENTES!$B$12:$G$2602,2,FALSE),"") -> INGENIERIA C Y G LIMITADA | F16: 267274 | G16: PUBLICIDAD | H16: 0 | I16: =IF(H16="","",IF(H16=0,"Contado","Crédito")) -> Contado | J16: =IF(I16="","",C16+H16) -> 45666 | K16: =IFERROR(IF(B16="","",IF(N16=0,0,J16-TODAY())),"") -> 0 | L16: =IF(I16="","",IF(N16=0,"Pagado",IF(K16<0,"Vencido","No vencido"))) -> Pagado | M16: =SUMIFS(Tabla_Pagos[IMPORTE ABONADO],Tabla_Pagos[FECHA DE ABONO],">0",Tabla_Pagos[NRO DOC],B16) -> 267274 | N16: =F16-M16 -> 0 | O16: {=MAX(IF((Tabla_Pagos[NRO DOC]=B16)*(Tabla_Pagos[IMPORTE ABONADO]>0),Tabla_Pagos[FECHA DE ABONO]))} -> 45666
B17: 889 | C17: 45666 | D17: 10730171-2 | E17: =IFERROR(VLOOKUP(D17,CLIENTES!$B$12:$G$2602,2,FALSE),"") -> LUIS MANUEL CONTRERAS YANEZ | F17: 30000 | G17: PUBLICIDAD | H17: 0 | I17: =IF(H17="","",IF(H17=0,"Contado","Crédito")) -> Contado | J17: =IF(I17="","",C17+H17) -> 45666 | K17: =IFERROR(IF(B17="","",IF(N17=0,0,J17-TODAY())),"") -> 0 | L17: =IF(I17="","",IF(N17=0,"Pagado",IF(K17<0,"Vencido","No vencido"))) -> Pagado | M17: =SUMIFS(Tabla_Pagos[IMPORTE ABONADO],Tabla_Pagos[FECHA DE ABONO],">0",Tabla_Pagos[NRO DOC],B17) -> 30000 | N17: =F17-M17 -> 0 | O17: {=MAX(IF((Tabla_Pagos[NRO DOC]=B17)*(Tabla_Pagos[IMPORTE ABONADO]>0),Tabla_Pagos[FECHA DE ABONO]))} -> 45666
B18: 890 | C18: 45666 | D18: 76506336-1 | E18: =IFERROR(VLOOKUP(D18,CLIENTES!$B$12:$G$2602,2,FALSE),"") -> KRADE SPA | F18: 47124 | G18: PUBLICIDAD | H18: 0 | I18: =IF(H18="","",IF(H18=0,"Contado","Crédito")) -> Contado | J18: =IF(I18="","",C18+H18) -> 45666 | K18: =IFERROR(IF(B18="","",IF(N18=0,0,J18-TODAY())),"") -> 0 | L18: =IF(I18="","",IF(N18=0,"Pagado",IF(K18<0,"Vencido","No vencido"))) -> Pagado | M18: =SUMIFS(Tabla_Pagos[IMPORTE ABONADO],Tabla_Pagos[FECHA DE ABONO],">0",Tabla_Pagos[NRO DOC],B18) -> 47124 | N18: =F18-M18 -> 0 | O18: {=MAX(IF((Tabla_Pagos[NRO DOC]=B18)*(Tabla_Pagos[IMPORTE ABONADO]>0),Tabla_Pagos[FECHA DE ABONO]))} -> 45666
B19: 891 | C19: 45667 | D19: 76478614-9 | E19: =IFERROR(VLOOKUP(D19,CLIENTES!$B$12:$G$2602,2,FALSE),"") -> INGENIERIA C Y G LIMITADA | F19: 377230 | G19: PUBLICIDAD | H19: 0 | I19: =IF(H19="","",IF(H19=0,"Contado","Crédito")) -> Contado | J19: =IF(I19="","",C19+H19) -> 45667 | K19: =IFERROR(IF(B19="","",IF(N19=0,0,J19-TODAY())),"") -> 0 | L19: =IF(I19="","",IF(N19=0,"Pagado",IF(K19<0,"Vencido","No vencido"))) -> Pagado | M19: =SUMIFS(Tabla_Pagos[IMPORTE ABONADO],Tabla_Pagos[FECHA DE ABONO],">0",Tabla_Pagos[NRO DOC],B19) -> 377230 | N19: =F19-M19 -> 0 | O19: {=MAX(IF((Tabla_Pagos[NRO DOC]=B19)*(Tabla_Pagos[IMPORTE ABONADO]>0),Tabla_Pagos[FECHA DE ABONO]))} -> 45667
B20: 892 | C20: 45668 | D20: 77176830-K | E20: =IFERROR(VLOOKUP(D20,CLIENTES!$B$12:$G$2602,2,FALSE),"") -> SOC COMERCIAL TRANSPORTES TAPE LTDA | F20: 107100 | G20: PUBLICIDAD | H20: 0 | I20: =IF(H20="","",IF(H20=0,"Contado","Crédito")) -> Contado | J20: =IF(I20="","",C20+H20) -> 45668 | K20: =IFERROR(IF(B20="","",IF(N20=0,0,J20-TODAY())),"") -> 0 | L20: =IF(I20="","",IF(N20=0,"Pagado",IF(K20<0,"Vencido","No vencido"))) -> Pagado | M20: =SUMIFS(Tabla_Pagos[IMPORTE ABONADO],Tabla_Pagos[FECHA DE ABONO],">0",Tabla_Pagos[NRO DOC],B20) -> 107100 | N20: =F20-M20 -> 0 | O20: {=MAX(IF((Tabla_Pagos[NRO DOC]=B20)*(Tabla_Pagos[IMPORTE ABONADO]>0),Tabla_Pagos[FECHA DE ABONO]))} -> 45668
B21: 893 | C21: 45668 | D21: 76862381-3 | E21: =IFERROR(VLOOKUP(D21,CLIENTES!$B$12:$G$2602,2,FALSE),"") -> SOCIEDAD COMERCIAL E INDUSTRIAL HYDRO CLEANING VAPOR LIMITADA | F21: 40001 | G21: PUBLICIDAD | H21: 0 | I21: =IF(H21="","",IF(H21=0,"Contado","Crédito")) -> Contado | J21: =IF(I21="","",C21+H21) -> 45668 | K21: =IFERROR(IF(B21="","",IF(N21=0,0,J21-TODAY())),"") -> 0 | L21: =IF(I21="","",IF(N21=0,"Pagado",IF(K21<0,"Vencido","No vencido"))) -> Pagado | M21: =SUMIFS(Tabla_Pagos[IMPORTE ABONADO],Tabla_Pagos[FECHA DE ABONO],">0",Tabla_Pagos[NRO DOC],B21) -> 40001 | N21: =F21-M21 -> 0 | O21: {=MAX(IF((Tabla_Pagos[NRO DOC]=B21)*(Tabla_Pagos[IMPORTE ABONADO]>0),Tabla_Pagos[FECHA DE ABONO]))} -> 45668
B22: 894 | C22: 45670 | D22: 76164075-5 | E22: =IFERROR(VLOOKUP(D22,CLIENTES!$B$12:$G$2602,2,FALSE),"") -> GRAU Y COMPANIA LIMITADA | F22: 100000 | G22: PUBLICIDAD | H22: 0 | I22: =IF(H22="","",IF(H22=0,"Contado","Crédito")) -> Contado | J22: =IF(I22="","",C22+H22) -> 45670 | K22: =IFERROR(IF(B22="","",IF(N22=0,0,J22-TODAY())),"") -> 0 | L22: =IF(I22="","",IF(N22=0,"Pagado",IF(K22<0,"Vencido","No vencido"))) -> Pagado | M22: =SUMIFS(Tabla_Pagos[IMPORTE ABONADO],Tabla_Pagos[FECHA DE ABONO],">0",Tabla_Pagos[NRO DOC],B22) -> 100000 | N22: =F22-M22 -> 0 | O22: {=MAX(IF((Tabla_Pagos[NRO DOC]=B22)*(Tabla_Pagos[IMPORTE ABONADO]>0),Tabla_Pagos[FECHA DE ABONO]))} -> 45670
B23: 895 | C23: 45671 | D23: 77137806-4 | E23: =IFERROR(VLOOKUP(D23,CLIENTES!$B$12:$G$2602,2,FALSE),"") -> CONSTRUCTORA GARY LIMITADA | F23: 540855 | G23: PUBLICIDAD | H23: 0 | I23: =IF(H23="","",IF(H23=0,"Contado","Crédito")) -> Contado | J23: =IF(I23="","",C23+H23) -> 45671 | K23: =IFERROR(IF(B23="","",IF(N23=0,0,J23-TODAY())),"") -> 0 | L23: =IF(I23="","",IF(N23=0,"Pagado",IF(K23<0,"Vencido","No vencido"))) -> Pagado | M23: =SUMIFS(Tabla_Pagos[IMPORTE ABONADO],Tabla_Pagos[FECHA DE ABONO],">0",Tabla_Pagos[NRO DOC],B23) -> 540855 | N23: =F23-M23 -> 0 | O23: {=MAX(IF((Tabla_Pagos[NRO DOC]=B23)*(Tabla_Pagos[IMPORTE ABONADO]>0),Tabla_Pagos[FECHA DE ABONO]))} -> 45671
... B653: 1562 | C653: 45961 | D653: 77437999-1 | E653: =IFERROR(VLOOKUP(D653,CLIENTES!$B$12:$G$2602,2,FALSE),"") -> INVERSIONES SAFUMAR LIMITADA | F653: 396746 | G653: PUBLICIDAD | H653: 30 | I653: =IF(H653="","",IF(H653=0,"Contado","Crédito")) -> Crédito | J653: =IF(I653="","",C653+H653) -> 45991 | K653: =IFERROR(IF(B653="","",IF(N653=0,0,J653-TODAY())),"") -> 0 | L653: =IF(I653="","",IF(N653=0,"Pagado",IF(K653<0,"Vencido","No vencido"))) -> Pagado | M653: =SUMIFS(Tabla_Pagos[IMPORTE ABONADO],Tabla_Pagos[FECHA DE ABONO],">0",Tabla_Pagos[NRO DOC],B653) -> 396746 | N653: =F653-M653 -> 0 | O653: {=MAX(IF((Tabla_Pagos[NRO DOC]=B653)*(Tabla_Pagos[IMPORTE ABONADO]>0),Tabla_Pagos[FECHA DE ABONO]))} -> 46043
B654: 1563 | C654: 45964 | D654: 76493582-9 | E654: SOCIEDAD DE SERVICIOS INVERSIONES Y COMERCIALIZADORA LEBAKSAF CHILE SPA | F654: 100000 | G654: PUBLICIDAD | H654: 0 | I654: =IF(H654="","",IF(H654=0,"Contado","Crédito")) -> Contado | J654: =IF(I654="","",C654+H654) -> 45964 | K654: =IFERROR(IF(B654="","",IF(N654=0,0,J654-TODAY())),"") -> 0 | L654: =IF(I654="","",IF(N654=0,"Pagado",IF(K654<0,"Vencido","No vencido"))) -> Pagado | M654: =SUMIFS(Tabla_Pagos[IMPORTE ABONADO],Tabla_Pagos[FECHA DE ABONO],">0",Tabla_Pagos[NRO DOC],B654) -> 100000 | N654: =F654-M654 -> 0 | O654: {=MAX(IF((Tabla_Pagos[NRO DOC]=B654)*(Tabla_Pagos[IMPORTE ABONADO]>0),Tabla_Pagos[FECHA DE ABONO]))} -> 45964
B655: 1564 | C655: 45964 | D655: 76059313-3 | E655: TRI CICLOS SOCIEDAD ANONIMA | F655: 176120 | G655: PUBLICIDAD | H655: 0 | I655: =IF(H655="","",IF(H655=0,"Contado","Crédito")) -> Contado | J655: =IF(I655="","",C655+H655) -> 45964 | K655: =IFERROR(IF(B655="","",IF(N655=0,0,J655-TODAY())),"") -> 0 | L655: =IF(I655="","",IF(N655=0,"Pagado",IF(K655<0,"Vencido","No vencido"))) -> Pagado | M655: =SUMIFS(Tabla_Pagos[IMPORTE ABONADO],Tabla_Pagos[FECHA DE ABONO],">0",Tabla_Pagos[NRO DOC],B655) -> 176120 | N655: =F655-M655 -> 0 | O655: {=MAX(IF((Tabla_Pagos[NRO DOC]=B655)*(Tabla_Pagos[IMPORTE ABONADO]>0),Tabla_Pagos[FECHA DE ABONO]))} -> 45964
B656: 1565 | C656: 45964 | D656: 76399731-6 | E656: RESMED TRANSPORTES LIMITADA | F656: 368900 | G656: PUBLICIDAD | H656: 0 | I656: =IF(H656="","",IF(H656=0,"Contado","Crédito")) -> Contado | J656: =IF(I656="","",C656+H656) -> 45964 | K656: =IFERROR(IF(B656="","",IF(N656=0,0,J656-TODAY())),"") -> 0 | L656: =IF(I656="","",IF(N656=0,"Pagado",IF(K656<0,"Vencido","No vencido"))) -> Pagado | M656: =SUMIFS(Tabla_Pagos[IMPORTE ABONADO],Tabla_Pagos[FECHA DE ABONO],">0",Tabla_Pagos[NRO DOC],B656) -> 368900 | N656: =F656-M656 -> 0 | O656: {=MAX(IF((Tabla_Pagos[NRO DOC]=B656)*(Tabla_Pagos[IMPORTE ABONADO]>0),Tabla_Pagos[FECHA DE ABONO]))} -> 45964
B657: 1566 | C657: 45964 | D657: 78320430-4 | E657: AUTOMOTRIZ NICOLAS LTDA. | F657: 119000 | G657: PUBLICIDAD | H657: 30 | I657: =IF(H657="","",IF(H657=0,"Contado","Crédito")) -> Crédito | J657: =IF(I657="","",C657+H657) -> 45994 | K657: =IFERROR(IF(B657="","",IF(N657=0,0,J657-TODAY())),"") -> 0 | L657: =IF(I657="","",IF(N657=0,"Pagado",IF(K657<0,"Vencido","No vencido"))) -> Pagado | M657: =SUMIFS(Tabla_Pagos[IMPORTE ABONADO],Tabla_Pagos[FECHA DE ABONO],">0",Tabla_Pagos[NRO DOC],B657) -> 119000 | N657: =F657-M657 -> 0 | O657: {=MAX(IF((Tabla_Pagos[NRO DOC]=B657)*(Tabla_Pagos[IMPORTE ABONADO]>0),Tabla_Pagos[FECHA DE ABONO]))} -> 45993
B658: 1567 | C658: 45965 | D658: 77744755-6 | E658: RID INGENIERÃA SPA | F658: 47600 | G658: PUBLICIDAD | H658: 0 | I658: =IF(H658="","",IF(H658=0,"Contado","Crédito")) -> Contado | J658: =IF(I658="","",C658+H658) -> 45965 | K658: =IFERROR(IF(B658="","",IF(N658=0,0,J658-TODAY())),"") -> 0 | L658: =IF(I658="","",IF(N658=0,"Pagado",IF(K658<0,"Vencido","No vencido"))) -> Pagado | M658: =SUMIFS(Tabla_Pagos[IMPORTE ABONADO],Tabla_Pagos[FECHA DE ABONO],">0",Tabla_Pagos[NRO DOC],B658) -> 47600 | N658: =F658-M658 -> 0 | O658: {=MAX(IF((Tabla_Pagos[NRO DOC]=B658)*(Tabla_Pagos[IMPORTE ABONADO]>0),Tabla_Pagos[FECHA DE ABONO]))} -> 45965
B659: 1568 | C659: 45965 | D659: 77723189-8 | E659: SEMINET SPA | F659: 59500 | G659: PUBLICIDAD | H659: 30 | I659: =IF(H659="","",IF(H659=0,"Contado","Crédito")) -> Crédito | J659: =IF(I659="","",C659+H659) -> 45995 | K659: =IFERROR(IF(B659="","",IF(N659=0,0,J659-TODAY())),"") -> 0 | L659: =IF(I659="","",IF(N659=0,"Pagado",IF(K659<0,"Vencido","No vencido"))) -> Pagado | M659: =SUMIFS(Tabla_Pagos[IMPORTE ABONADO],Tabla_Pagos[FECHA DE ABONO],">0",Tabla_Pagos[NRO DOC],B659) -> 59500 | N659: =F659-M659 -> 0 | O659: {=MAX(IF((Tabla_Pagos[NRO DOC]=B659)*(Tabla_Pagos[IMPORTE ABONADO]>0),Tabla_Pagos[FECHA DE ABONO]))} -> 45975
B660: 1569 | C660: 45958 | D660: 77840923-2 | E660: INGENIERIA GACITUA SPA | F660: 89250 | G660: PUBLICIDAD | H660: 0 | I660: =IF(H660="","",IF(H660=0,"Contado","Crédito")) -> Contado | J660: =IF(I660="","",C660+H660) -> 45958 | K660: =IFERROR(IF(B660="","",IF(N660=0,0,J660-TODAY())),"") -> 0 | L660: =IF(I660="","",IF(N660=0,"Pagado",IF(K660<0,"Vencido","No vencido"))) -> Pagado | M660: =SUMIFS(Tabla_Pagos[IMPORTE ABONADO],Tabla_Pagos[FECHA DE ABONO],">0",Tabla_Pagos[NRO DOC],B660) -> 89250 | N660: =F660-M660 -> 0 | O660: {=MAX(IF((Tabla_Pagos[NRO DOC]=B660)*(Tabla_Pagos[IMPORTE ABONADO]>0),Tabla_Pagos[FECHA DE ABONO]))} -> 45958
B661: 1570 | C661: 45966 | D661: 77744755-6 | E661: RID INGENIERÃA SPA | F661: 35700 | G661: PUBLICIDAD | H661: 0 | I661: =IF(H661="","",IF(H661=0,"Contado","Crédito")) -> Contado | J661: =IF(I661="","",C661+H661) -> 45966 | K661: =IFERROR(IF(B661="","",IF(N661=0,0,J661-TODAY())),"") -> 0 | L661: =IF(I661="","",IF(N661=0,"Pagado",IF(K661<0,"Vencido","No vencido"))) -> Pagado | M661: =SUMIFS(Tabla_Pagos[IMPORTE ABONADO],Tabla_Pagos[FECHA DE ABONO],">0",Tabla_Pagos[NRO DOC],B661) -> 35700 | N661: =F661-M661 -> 0 | O661: {=MAX(IF((Tabla_Pagos[NRO DOC]=B661)*(Tabla_Pagos[IMPORTE ABONADO]>0),Tabla_Pagos[FECHA DE ABONO]))} -> 45966
B662: 1571 | C662: 45966 | D662: 77578446-6 | E662: JOYERIA Y RELOJERIA KARIME DAU SPA | F662: 840426 | G662: PUBLICIDAD | H662: 0 | I662: =IF(H662="","",IF(H662=0,"Contado","Crédito")) -> Contado | J662: =IF(I662="","",C662+H662) -> 45966 | K662: =IFERROR(IF(B662="","",IF(N662=0,0,J662-TODAY())),"") -> 0 | L662: =IF(I662="","",IF(N662=0,"Pagado",IF(K662<0,"Vencido","No vencido"))) -> Pagado | M662: =SUMIFS(Tabla_Pagos[IMPORTE ABONADO],Tabla_Pagos[FECHA DE ABONO],">0",Tabla_Pagos[NRO DOC],B662) -> 840426 | N662: =F662-M662 -> 0 | O662: {=MAX(IF((Tabla_Pagos[NRO DOC]=B662)*(Tabla_Pagos[IMPORTE ABONADO]>0),Tabla_Pagos[FECHA DE ABONO]))} -> 45966
B663: 1572 | C663: 45967 | D663: 76686138-5 | E663: SKC RED SPA | F663: 83300 | G663: PUBLICIDAD | H663: 30 | I663: =IF(H663="","",IF(H663=0,"Contado","Crédito")) -> Crédito | J663: =IF(I663="","",C663+H663) -> 45997 | K663: =IFERROR(IF(B663="","",IF(N663=0,0,J663-TODAY())),"") -> 0 | L663: =IF(I663="","",IF(N663=0,"Pagado",IF(K663<0,"Vencido","No vencido"))) -> Pagado | M663: =SUMIFS(Tabla_Pagos[IMPORTE ABONADO],Tabla_Pagos[FECHA DE ABONO],">0",Tabla_Pagos[NRO DOC],B663) -> 83300 | N663: =F663-M663 -> 0 | O663: {=MAX(IF((Tabla_Pagos[NRO DOC]=B663)*(Tabla_Pagos[IMPORTE ABONADO]>0),Tabla_Pagos[FECHA DE ABONO]))} -> 45982
B664: 1573 | C664: 45967 | D664: 76921814-9 | E664: JUAN ALBERTO CALDERON GUTIERREZ TRANSPORTE DE PERSONAL EMPRESA INDIVIDUAL | F664: 65450 | G664: PUBLICIDAD | H664: 0 | I664: =IF(H664="","",IF(H664=0,"Contado","Crédito")) -> Contado | J664: =IF(I664="","",C664+H664) -> 45967 | K664: =IFERROR(IF(B664="","",IF(N664=0,0,J664-TODAY())),"") -> 0 | L664: =IF(I664="","",IF(N664=0,"Pagado",IF(K664<0,"Vencido","No vencido"))) -> Pagado | M664: =SUMIFS(Tabla_Pagos[IMPORTE ABONADO],Tabla_Pagos[FECHA DE ABONO],">0",Tabla_Pagos[NRO DOC],B664) -> 65450 | N664: =F664-M664 -> 0 | O664: {=MAX(IF((Tabla_Pagos[NRO DOC]=B664)*(Tabla_Pagos[IMPORTE ABONADO]>0),Tabla_Pagos[FECHA DE ABONO]))} -> 45967
B665: 1574 | C665: 45967 | D665: 77841885-1 | E665: TRANSPORTES TOLECAR SPA | F665: 65450 | G665: PUBLICIDAD | H665: 0 | I665: =IF(H665="","",IF(H665=0,"Contado","Crédito")) -> Contado | J665: =IF(I665="","",C665+H665) -> 45967 | K665: =IFERROR(IF(B665="","",IF(N665=0,0,J665-TODAY())),"") -> 0 | L665: =IF(I665="","",IF(N665=0,"Pagado",IF(K665<0,"Vencido","No vencido"))) -> Pagado | M665: =SUMIFS(Tabla_Pagos[IMPORTE ABONADO],Tabla_Pagos[FECHA DE ABONO],">0",Tabla_Pagos[NRO DOC],B665) -> 65450 | N665: =F665-M665 -> 0 | O665: {=MAX(IF((Tabla_Pagos[NRO DOC]=B665)*(Tabla_Pagos[IMPORTE ABONADO]>0),Tabla_Pagos[FECHA DE ABONO]))} -> 45967
... B678: 1588 | C678: 45973 | D678: 76920615-9 | E678: SOCIEDAD COMERCIAL RODRIGO URBANO SPA | F678: 70329 | G678: PUBLICIDAD | H678: 0 | I678: =IF(H678="","",IF(H678=0,"Contado","Crédito")) -> Contado | J678: =IF(I678="","",C678+H678) -> 45973 | K678: =IFERROR(IF(B678="","",IF(N678=0,0,J678-TODAY())),"") -> 0 | L678: =IF(I678="","",IF(N678=0,"Pagado",IF(K678<0,"Vencido","No vencido"))) -> Pagado | M678: =SUMIFS(Tabla_Pagos[IMPORTE ABONADO],Tabla_Pagos[FECHA DE ABONO],">0",Tabla_Pagos[NRO DOC],B678) -> 70329 | N678: =F678-M678 -> 0 | O678: {=MAX(IF((Tabla_Pagos[NRO DOC]=B678)*(Tabla_Pagos[IMPORTE ABONADO]>0),Tabla_Pagos[FECHA DE ABONO]))} -> 45973
B679: 1589 | C679: 45973 | D679: 83628100-4 | E679: =IFERROR(VLOOKUP(D679,CLIENTES!$B$12:$G$2602,2,FALSE),"") -> SONDA S A | F679: 132804 | G679: PUBLICIDAD | H679: 0 | I679: =IF(H679="","",IF(H679=0,"Contado","Crédito")) -> Contado | J679: =IF(I679="","",C679+H679) -> 45973 | K679: =IFERROR(IF(B679="","",IF(N679=0,0,J679-TODAY())),"") -> 0 | L679: =IF(I679="","",IF(N679=0,"Pagado",IF(K679<0,"Vencido","No vencido"))) -> Pagado | M679: =SUMIFS(Tabla_Pagos[IMPORTE ABONADO],Tabla_Pagos[FECHA DE ABONO],">0",Tabla_Pagos[NRO DOC],B679) -> 132804 | N679: =F679-M679 -> 0 | O679: {=MAX(IF((Tabla_Pagos[NRO DOC]=B679)*(Tabla_Pagos[IMPORTE ABONADO]>0),Tabla_Pagos[FECHA DE ABONO]))} -> 45973
B680: 1590 | C680: 45973 | D680: 77382153-4 | E680: =IFERROR(VLOOKUP(D680,CLIENTES!$B$12:$G$2602,2,FALSE),"") -> AUCAN LOGISTIC SPA | F680: 696150 | G680: PUBLICIDAD | H680: 0 | I680: =IF(H680="","",IF(H680=0,"Contado","Crédito")) -> Contado | J680: =IF(I680="","",C680+H680) -> 45973 | K680: =IFERROR(IF(B680="","",IF(N680=0,0,J680-TODAY())),"") -> 0 | L680: =IF(I680="","",IF(N680=0,"Pagado",IF(K680<0,"Vencido","No vencido"))) -> Pagado | M680: =SUMIFS(Tabla_Pagos[IMPORTE ABONADO],Tabla_Pagos[FECHA DE ABONO],">0",Tabla_Pagos[NRO DOC],B680) -> 696150 | N680: =F680-M680 -> 0 | O680: {=MAX(IF((Tabla_Pagos[NRO DOC]=B680)*(Tabla_Pagos[IMPORTE ABONADO]>0),Tabla_Pagos[FECHA DE ABONO]))} -> 45973
B681: 1591 | C681: 45974 | D681: 76410595-8 | E681: =IFERROR(VLOOKUP(D681,CLIENTES!$B$12:$G$2602,2,FALSE),"") -> CROSAN SPA | F681: 1320900 | G681: PUBLICIDAD | H681: 30 | I681: =IF(H681="","",IF(H681=0,"Contado","Crédito")) -> Crédito | J681: =IF(I681="","",C681+H681) -> 46004 | K681: =IFERROR(IF(B681="","",IF(N681=0,0,J681-TODAY())),"") -> 0 | L681: =IF(I681="","",IF(N681=0,"Pagado",IF(K681<0,"Vencido","No vencido"))) -> Pagado | M681: =SUMIFS(Tabla_Pagos[IMPORTE ABONADO],Tabla_Pagos[FECHA DE ABONO],">0",Tabla_Pagos[NRO DOC],B681) -> 1320900 | N681: =F681-M681 -> 0 | O681: {=MAX(IF((Tabla_Pagos[NRO DOC]=B681)*(Tabla_Pagos[IMPORTE ABONADO]>0),Tabla_Pagos[FECHA DE ABONO]))} -> 46007
B682: 1592 | C682: 45974 | D682: 10193231-1 | E682: =IFERROR(VLOOKUP(D682,CLIENTES!$B$12:$G$2602,2,FALSE),"") -> DAVID VIEYRA FELDMAN | F682: 380800 | G682: PUBLICIDAD | H682: 0 | I682: =IF(H682="","",IF(H682=0,"Contado","Crédito")) -> Contado | J682: =IF(I682="","",C682+H682) -> 45974 | K682: =IFERROR(IF(B682="","",IF(N682=0,0,J682-TODAY())),"") -> 0 | L682: =IF(I682="","",IF(N682=0,"Pagado",IF(K682<0,"Vencido","No vencido"))) -> Pagado | M682: =SUMIFS(Tabla_Pagos[IMPORTE ABONADO],Tabla_Pagos[FECHA DE ABONO],">0",Tabla_Pagos[NRO DOC],B682) -> 380800 | N682: =F682-M682 -> 0 | O682: {=MAX(IF((Tabla_Pagos[NRO DOC]=B682)*(Tabla_Pagos[IMPORTE ABONADO]>0),Tabla_Pagos[FECHA DE ABONO]))} -> 45974
B683: 1593 | C683: 45974 | D683: 77323546-5 | E683: =IFERROR(VLOOKUP(D683,CLIENTES!$B$12:$G$2602,2,FALSE),"") -> MLV SPA | F683: 32130 | G683: PUBLICIDAD | H683: 0 | I683: =IF(H683="","",IF(H683=0,"Contado","Crédito")) -> Contado | J683: =IF(I683="","",C683+H683) -> 45974 | K683: =IFERROR(IF(B683="","",IF(N683=0,0,J683-TODAY())),"") -> 0 | L683: =IF(I683="","",IF(N683=0,"Pagado",IF(K683<0,"Vencido","No vencido"))) -> Pagado | M683: =SUMIFS(Tabla_Pagos[IMPORTE ABONADO],Tabla_Pagos[FECHA DE ABONO],">0",Tabla_Pagos[NRO DOC],B683) -> 32130 | N683: =F683-M683 -> 0 | O683: {=MAX(IF((Tabla_Pagos[NRO DOC]=B683)*(Tabla_Pagos[IMPORTE ABONADO]>0),Tabla_Pagos[FECHA DE ABONO]))} -> 45974
B684: 1594 | C684: 45975 | D684: 77511008-2 | E684: =IFERROR(VLOOKUP(D684,CLIENTES!$B$12:$G$2602,2,FALSE),"") -> MULTISERVICIOS SANABRIA SPA | F684: 133213 | G684: PUBLICIDAD | H684: 0 | I684: =IF(H684="","",IF(H684=0,"Contado","Crédito")) -> Contado | J684: =IF(I684="","",C684+H684) -> 45975 | K684: =IFERROR(IF(B684="","",IF(N684=0,0,J684-TODAY())),"") -> 0 | L684: =IF(I684="","",IF(N684=0,"Pagado",IF(K684<0,"Vencido","No vencido"))) -> Pagado | M684: =SUMIFS(Tabla_Pagos[IMPORTE ABONADO],Tabla_Pagos[FECHA DE ABONO],">0",Tabla_Pagos[NRO DOC],B684) -> 133213 | N684: =F684-M684 -> 0 | O684: {=MAX(IF((Tabla_Pagos[NRO DOC]=B684)*(Tabla_Pagos[IMPORTE ABONADO]>0),Tabla_Pagos[FECHA DE ABONO]))} -> 45975
B685: 1595 | C685: 45975 | D685: 83628100-4 | E685: =IFERROR(VLOOKUP(D685,CLIENTES!$B$12:$G$2602,2,FALSE),"") -> SONDA S A | F685: 125188 | G685: PUBLICIDAD | H685: 0 | I685: =IF(H685="","",IF(H685=0,"Contado","Crédito")) -> Contado | J685: =IF(I685="","",C685+H685) -> 45975 | K685: =IFERROR(IF(B685="","",IF(N685=0,0,J685-TODAY())),"") -> 0 | L685: =IF(I685="","",IF(N685=0,"Pagado",IF(K685<0,"Vencido","No vencido"))) -> Pagado | M685: =SUMIFS(Tabla_Pagos[IMPORTE ABONADO],Tabla_Pagos[FECHA DE ABONO],">0",Tabla_Pagos[NRO DOC],B685) -> 125188 | N685: =F685-M685 -> 0 | O685: {=MAX(IF((Tabla_Pagos[NRO DOC]=B685)*(Tabla_Pagos[IMPORTE ABONADO]>0),Tabla_Pagos[FECHA DE ABONO]))} -> 45975
B686: 1596 | C686: 45978 | D686: 76272239-9 | E686: =IFERROR(VLOOKUP(D686,CLIENTES!$B$12:$G$2602,2,FALSE),"") -> INSTITUTO INTEGRAL DE SALUD OCUPACIONAL SPA | F686: 142800 | G686: PUBLICIDAD | H686: 30 | I686: =IF(H686="","",IF(H686=0,"Contado","Crédito")) -> Crédito | J686: =IF(I686="","",C686+H686) -> 46008 | K686: =IFERROR(IF(B686="","",IF(N686=0,0,J686-TODAY())),"") -> 0 | L686: =IF(I686="","",IF(N686=0,"Pagado",IF(K686<0,"Vencido","No vencido"))) -> Pagado | M686: =SUMIFS(Tabla_Pagos[IMPORTE ABONADO],Tabla_Pagos[FECHA DE ABONO],">0",Tabla_Pagos[NRO DOC],B686) -> 142800 | N686: =F686-M686 -> 0 | O686: {=MAX(IF((Tabla_Pagos[NRO DOC]=B686)*(Tabla_Pagos[IMPORTE ABONADO]>0),Tabla_Pagos[FECHA DE ABONO]))} -> 46027
B687: 1597 | C687: 45978 | D687: 77919041-2 | E687: =IFERROR(VLOOKUP(D687,CLIENTES!$B$12:$G$2602,2,FALSE),"") -> MUNDO CORPORATIVO SPA | F687: 190400 | G687: PUBLICIDAD | H687: 30 | I687: =IF(H687="","",IF(H687=0,"Contado","Crédito")) -> Crédito | J687: =IF(I687="","",C687+H687) -> 46008 | K687: =IFERROR(IF(B687="","",IF(N687=0,0,J687-TODAY())),"") -> -170 | L687: =IF(I687="","",IF(N687=0,"Pagado",IF(K687<0,"Vencido","No vencido"))) -> Vencido | M687: =SUMIFS(Tabla_Pagos[IMPORTE ABONADO],Tabla_Pagos[FECHA DE ABONO],">0",Tabla_Pagos[NRO DOC],B687) -> 0 | N687: =F687-M687 -> 190400 | O687: {=MAX(IF((Tabla_Pagos[NRO DOC]=B687)*(Tabla_Pagos[IMPORTE ABONADO]>0),Tabla_Pagos[FECHA DE ABONO]))} -> 0
B688: 1598 | C688: 45978 | D688: 77062894-6 | E688: =IFERROR(VLOOKUP(D688,CLIENTES!$B$12:$G$2602,2,FALSE),"") -> MENDOZA CAZ SPA | F688: 253470 | G688: PUBLICIDAD | H688: 0 | I688: =IF(H688="","",IF(H688=0,"Contado","Crédito")) -> Contado | J688: =IF(I688="","",C688+H688) -> 45978 | K688: =IFERROR(IF(B688="","",IF(N688=0,0,J688-TODAY())),"") -> 0 | L688: =IF(I688="","",IF(N688=0,"Pagado",IF(K688<0,"Vencido","No vencido"))) -> Pagado | M688: =SUMIFS(Tabla_Pagos[IMPORTE ABONADO],Tabla_Pagos[FECHA DE ABONO],">0",Tabla_Pagos[NRO DOC],B688) -> 253470 | N688: =F688-M688 -> 0 | O688: {=MAX(IF((Tabla_Pagos[NRO DOC]=B688)*(Tabla_Pagos[IMPORTE ABONADO]>0),Tabla_Pagos[FECHA DE ABONO]))} -> 45978
B689: 1599 | C689: 45978 | D689: 96792430-K | E689: =IFERROR(VLOOKUP(D689,CLIENTES!$B$12:$G$2602,2,FALSE),"") -> SODIMAC S.A. | F689: 2299675 | G689: PUBLICIDAD | H689: 30 | I689: =IF(H689="","",IF(H689=0,"Contado","Crédito")) -> Crédito | J689: =IF(I689="","",C689+H689) -> 46008 | K689: =IFERROR(IF(B689="","",IF(N689=0,0,J689-TODAY())),"") -> 0 | L689: =IF(I689="","",IF(N689=0,"Pagado",IF(K689<0,"Vencido","No vencido"))) -> Pagado | M689: =SUMIFS(Tabla_Pagos[IMPORTE ABONADO],Tabla_Pagos[FECHA DE ABONO],">0",Tabla_Pagos[NRO DOC],B689) -> 2299675 | N689: =F689-M689 -> 0 | O689: {=MAX(IF((Tabla_Pagos[NRO DOC]=B689)*(Tabla_Pagos[IMPORTE ABONADO]>0),Tabla_Pagos[FECHA DE ABONO]))} -> 46008
B690: 1600 | C690: 45979 | D690: 77511008-2 | E690: =IFERROR(VLOOKUP(D690,CLIENTES!$B$12:$G$2602,2,FALSE),"") -> MULTISERVICIOS SANABRIA SPA | F690: 121380 | G690: PUBLICIDAD | H690: 0 | I690: =IF(H690="","",IF(H690=0,"Contado","Crédito")) -> Contado | J690: =IF(I690="","",C690+H690) -> 45979 | K690: =IFERROR(IF(B690="","",IF(N690=0,0,J690-TODAY())),"") -> 0 | L690: =IF(I690="","",IF(N690=0,"Pagado",IF(K690<0,"Vencido","No vencido"))) -> Pagado | M690: =SUMIFS(Tabla_Pagos[IMPORTE ABONADO],Tabla_Pagos[FECHA DE ABONO],">0",Tabla_Pagos[NRO DOC],B690) -> 121380 | N690: =F690-M690 -> 0 | O690: {=MAX(IF((Tabla_Pagos[NRO DOC]=B690)*(Tabla_Pagos[IMPORTE ABONADO]>0),Tabla_Pagos[FECHA DE ABONO]))} -> 45979
... B1108: 2050 | C1108: 46167 | D1108: 76744135-5 | E1108: =IFERROR(VLOOKUP(D1108,CLIENTES!$B$12:$G$2602,2,FALSE),"") -> PATAGONIA SERVICIOS SPA | F1108: 1148350 | G1108: PUBLICIDAD | H1108: 0 | I1108: =IF(H1108="","",IF(H1108=0,"Contado","Crédito")) -> Contado | J1108: =IF(I1108="","",C1108+H1108) -> 46167 | K1108: =IFERROR(IF(B1108="","",IF(N1108=0,0,J1108-TODAY())),"") -> -11 | L1108: =IF(I1108="","",IF(N1108=0,"Pagado",IF(K1108<0,"Vencido","No vencido"))) -> Vencido | M1108: =SUMIFS(Tabla_Pagos[IMPORTE ABONADO],Tabla_Pagos[FECHA DE ABONO],">0",Tabla_Pagos[NRO DOC],B1108) -> 0 | N1108: =F1108-M1108 -> 1148350 | O1108: {=MAX(IF((Tabla_Pagos[NRO DOC]=B1108)*(Tabla_Pagos[IMPORTE ABONADO]>0),Tabla_Pagos[FECHA DE ABONO]))} -> 0
...

Sheet ABONOS
C11: NRO DOC | D11: FECHA DE EMISIÓN | E11: COD CLIENTE | F11: CLIENTE | G11: IMPORTE DEL DOC. | H11: GLOSA | I11: IMPORTE ABONADO | J11: FECHA DE ABONO
C12: 884 | D12: =IFERROR(VLOOKUP($C12,Tabla_Documentos[],2,FALSE),"") -> 45661 | E12: =IFERROR(VLOOKUP($C12,Tabla_Documentos[],3,FALSE),"") -> 77361091-6 | F12: =IFERROR(VLOOKUP($C12,Tabla_Documentos[],4,FALSE),"") -> OSSAVAL SPA | G12: =IFERROR(VLOOKUP($C12,Tabla_Documentos[],5,FALSE),"") -> 83300 | H12: =IFERROR(VLOOKUP($C12,Tabla_Documentos[],6,FALSE),"") -> PUBLICIDAD | I12: =IFERROR(VLOOKUP($C12,Tabla_Documentos[],5,FALSE),"") -> 83300 | J12: 45661
C13: 885 | D13: =IFERROR(VLOOKUP($C13,Tabla_Documentos[],2,FALSE),"") -> 45661 | E13: =IFERROR(VLOOKUP($C13,Tabla_Documentos[],3,FALSE),"") -> 77137806-4 | F13: =IFERROR(VLOOKUP($C13,Tabla_Documentos[],4,FALSE),"") -> CONSTRUCTORA GARY LIMITADA | G13: =IFERROR(VLOOKUP($C13,Tabla_Documentos[],5,FALSE),"") -> 163030 | H13: =IFERROR(VLOOKUP($C13,Tabla_Documentos[],6,FALSE),"") -> PUBLICIDAD | I13: =IFERROR(VLOOKUP($C13,Tabla_Documentos[],5,FALSE),"") -> 163030 | J13: 45661
C14: 886 | D14: =IFERROR(VLOOKUP($C14,Tabla_Documentos[],2,FALSE),"") -> 45661 | E14: =IFERROR(VLOOKUP($C14,Tabla_Documentos[],3,FALSE),"") -> 77758444-8 | F14: =IFERROR(VLOOKUP($C14,Tabla_Documentos[],4,FALSE),"") -> TRANSPORTE DOBLE C SPA | G14: =IFERROR(VLOOKUP($C14,Tabla_Documentos[],5,FALSE),"") -> 166600 | H14: =IFERROR(VLOOKUP($C14,Tabla_Documentos[],6,FALSE),"") -> PUBLICIDAD | I14: =IFERROR(VLOOKUP($C14,Tabla_Documentos[],5,FALSE),"") -> 166600 | J14: 45661
C15: 887 | D15: =IFERROR(VLOOKUP($C15,Tabla_Documentos[],2,FALSE),"") -> 45663 | E15: =IFERROR(VLOOKUP($C15,Tabla_Documentos[],3,FALSE),"") -> 77907297-5 | F15: =IFERROR(VLOOKUP($C15,Tabla_Documentos[],4,FALSE),"") -> LEYARZ SPA | G15: =IFERROR(VLOOKUP($C15,Tabla_Documentos[],5,FALSE),"") -> 142800 | H15: =IFERROR(VLOOKUP($C15,Tabla_Documentos[],6,FALSE),"") -> PUBLICIDAD | I15: =IFERROR(VLOOKUP($C15,Tabla_Documentos[],5,FALSE),"") -> 142800 | J15: 45663
C16: 888 | D16: =IFERROR(VLOOKUP($C16,Tabla_Documentos[],2,FALSE),"") -> 45666 | E16: =IFERROR(VLOOKUP($C16,Tabla_Documentos[],3,FALSE),"") -> 76478614-9 | F16: =IFERROR(VLOOKUP($C16,Tabla_Documentos[],4,FALSE),"") -> INGENIERIA C Y G LIMITADA | G16: =IFERROR(VLOOKUP($C16,Tabla_Documentos[],5,FALSE),"") -> 267274 | H16: =IFERROR(VLOOKUP($C16,Tabla_Documentos[],6,FALSE),"") -> PUBLICIDAD | I16: =IFERROR(VLOOKUP($C16,Tabla_Documentos[],5,FALSE),"") -> 267274 | J16: 45666
C17: 889 | D17: =IFERROR(VLOOKUP($C17,Tabla_Documentos[],2,FALSE),"") -> 45666 | E17: =IFERROR(VLOOKUP($C17,Tabla_Documentos[],3,FALSE),"") -> 10730171-2 | F17: =IFERROR(VLOOKUP($C17,Tabla_Documentos[],4,FALSE),"") -> LUIS MANUEL CONTRERAS YANEZ | G17: =IFERROR(VLOOKUP($C17,Tabla_Documentos[],5,FALSE),"") -> 30000 | H17: =IFERROR(VLOOKUP($C17,Tabla_Documentos[],6,FALSE),"") -> PUBLICIDAD | I17: =IFERROR(VLOOKUP($C17,Tabla_Documentos[],5,FALSE),"") -> 30000 | J17: 45666
C18: 890 | D18: =IFERROR(VLOOKUP($C18,Tabla_Documentos[],2,FALSE),"") -> 45666 | E18: =IFERROR(VLOOKUP($C18,Tabla_Documentos[],3,FALSE),"") -> 76506336-1 | F18: =IFERROR(VLOOKUP($C18,Tabla_Documentos[],4,FALSE),"") -> KRADE SPA | G18: =IFERROR(VLOOKUP($C18,Tabla_Documentos[],5,FALSE),"") -> 47124 | H18: =IFERROR(VLOOKUP($C18,Tabla_Documentos[],6,FALSE),"") -> PUBLICIDAD | I18: =IFERROR(VLOOKUP($C18,Tabla_Documentos[],5,FALSE),"") -> 47124 | J18: 45666
C19: 891 | D19: =IFERROR(VLOOKUP($C19,Tabla_Documentos[],2,FALSE),"") -> 45667 | E19: =IFERROR(VLOOKUP($C19,Tabla_Documentos[],3,FALSE),"") -> 76478614-9 | F19: =IFERROR(VLOOKUP($C19,Tabla_Documentos[],4,FALSE),"") -> INGENIERIA C Y G LIMITADA | G19: =IFERROR(VLOOKUP($C19,Tabla_Documentos[],5,FALSE),"") -> 377230 | H19: =IFERROR(VLOOKUP($C19,Tabla_Documentos[],6,FALSE),"") -> PUBLICIDAD | I19: =IFERROR(VLOOKUP($C19,Tabla_Documentos[],5,FALSE),"") -> 377230 | J19: 45667
C20: 892 | D20: =IFERROR(VLOOKUP($C20,Tabla_Documentos[],2,FALSE),"") -> 45668 | E20: =IFERROR(VLOOKUP($C20,Tabla_Documentos[],3,FALSE),"") -> 77176830-K | F20: =IFERROR(VLOOKUP($C20,Tabla_Documentos[],4,FALSE),"") -> SOC COMERCIAL TRANSPORTES TAPE LTDA | G20: =IFERROR(VLOOKUP($C20,Tabla_Documentos[],5,FALSE),"") -> 107100 | H20: =IFERROR(VLOOKUP($C20,Tabla_Documentos[],6,FALSE),"") -> PUBLICIDAD | I20: =IFERROR(VLOOKUP($C20,Tabla_Documentos[],5,FALSE),"") -> 107100 | J20: 45668
C21: 893 | D21: =IFERROR(VLOOKUP($C21,Tabla_Documentos[],2,FALSE),"") -> 45668 | E21: =IFERROR(VLOOKUP($C21,Tabla_Documentos[],3,FALSE),"") -> 76862381-3 | F21: =IFERROR(VLOOKUP($C21,Tabla_Documentos[],4,FALSE),"") -> SOCIEDAD COMERCIAL E INDUSTRIAL HYDRO CLEANING VAPOR LIMITADA | G21: =IFERROR(VLOOKUP($C21,Tabla_Documentos[],5,FALSE),"") -> 40001 | H21: =IFERROR(VLOOKUP($C21,Tabla_Documentos[],6,FALSE),"") -> PUBLICIDAD | I21: =IFERROR(VLOOKUP($C21,Tabla_Documentos[],5,FALSE),"") -> 40001 | J21: 45668
C22: 894 | D22: =IFERROR(VLOOKUP($C22,Tabla_Documentos[],2,FALSE),"") -> 45670 | E22: =IFERROR(VLOOKUP($C22,Tabla_Documentos[],3,FALSE),"") -> 76164075-5 | F22: =IFERROR(VLOOKUP($C22,Tabla_Documentos[],4,FALSE),"") -> GRAU Y COMPANIA LIMITADA | G22: =IFERROR(VLOOKUP($C22,Tabla_Documentos[],5,FALSE),"") -> 100000 | H22: =IFERROR(VLOOKUP($C22,Tabla_Documentos[],6,FALSE),"") -> PUBLICIDAD | I22: =IFERROR(VLOOKUP($C22,Tabla_Documentos[],5,FALSE),"") -> 100000 | J22: 45670
C23: 895 | D23: =IFERROR(VLOOKUP($C23,Tabla_Documentos[],2,FALSE),"") -> 45671 | E23: =IFERROR(VLOOKUP($C23,Tabla_Documentos[],3,FALSE),"") -> 77137806-4 | F23: =IFERROR(VLOOKUP($C23,Tabla_Documentos[],4,FALSE),"") -> CONSTRUCTORA GARY LIMITADA | G23: =IFERROR(VLOOKUP($C23,Tabla_Documentos[],5,FALSE),"") -> 540855 | H23: =IFERROR(VLOOKUP($C23,Tabla_Documentos[],6,FALSE),"") -> PUBLICIDAD | I23: =IFERROR(VLOOKUP($C23,Tabla_Documentos[],5,FALSE),"") -> 540855 | J23: 45671
... C480: 1386 | D480: =IFERROR(VLOOKUP($C480,Tabla_Documentos[],2,FALSE),"") -> 45874 | E480: =IFERROR(VLOOKUP($C480,Tabla_Documentos[],3,FALSE),"") -> 9364286-4 | F480: =IFERROR(VLOOKUP($C480,Tabla_Documentos[],4,FALSE),"") -> GUILLERMO EDUARDO PACHECO BOLADO | G480: =IFERROR(VLOOKUP($C480,Tabla_Documentos[],5,FALSE),"") -> 17850 | H480: =IFERROR(VLOOKUP($C480,Tabla_Documentos[],6,FALSE),"") -> BELEN | I480: =IFERROR(VLOOKUP($C480,Tabla_Documentos[],5,FALSE),"") -> 17850 | J480: 45874
C481: 1387 | D481: =IFERROR(VLOOKUP($C481,Tabla_Documentos[],2,FALSE),"") -> 45874 | E481: =IFERROR(VLOOKUP($C481,Tabla_Documentos[],3,FALSE),"") -> 76744135-5 | F481: =IFERROR(VLOOKUP($C481,Tabla_Documentos[],4,FALSE),"") -> PATAGONIA SERVICIOS SPA | G481: =IFERROR(VLOOKUP($C481,Tabla_Documentos[],5,FALSE),"") -> 17850000 | H481: =IFERROR(VLOOKUP($C481,Tabla_Documentos[],6,FALSE),"") -> PUBLICIDAD | I481: 5850000 | J481: 45939
C482: 1387 | D482: =IFERROR(VLOOKUP($C482,Tabla_Documentos[],2,FALSE),"") -> 45874 | E482: =IFERROR(VLOOKUP($C482,Tabla_Documentos[],3,FALSE),"") -> 76744135-5 | F482: =IFERROR(VLOOKUP($C482,Tabla_Documentos[],4,FALSE),"") -> PATAGONIA SERVICIOS SPA | G482: =IFERROR(VLOOKUP($C482,Tabla_Documentos[],5,FALSE),"") -> 17850000 | H482: =IFERROR(VLOOKUP($C482,Tabla_Documentos[],6,FALSE),"") -> PUBLICIDAD | I482: 7000000 | J482: 45939
C483: 1387 | D483: =IFERROR(VLOOKUP($C483,Tabla_Documentos[],2,FALSE),"") -> 45874 | E483: =IFERROR(VLOOKUP($C483,Tabla_Documentos[],3,FALSE),"") -> 76744135-5 | F483: =IFERROR(VLOOKUP($C483,Tabla_Documentos[],4,FALSE),"") -> PATAGONIA SERVICIOS SPA | G483: =IFERROR(VLOOKUP($C483,Tabla_Documentos[],5,FALSE),"") -> 17850000 | H483: =IFERROR(VLOOKUP($C483,Tabla_Documentos[],6,FALSE),"") -> PUBLICIDAD | I483: 5000000 | J483: 45946
C484: 1388 | D484: =IFERROR(VLOOKUP($C484,Tabla_Documentos[],2,FALSE),"") -> 45875 | E484: =IFERROR(VLOOKUP($C484,Tabla_Documentos[],3,FALSE),"") -> 99505900-2 | F484: =IFERROR(VLOOKUP($C484,Tabla_Documentos[],4,FALSE),"") -> DISTRIBUIDORA DE EXPLOSIVOS Y ACCESORIOS S A | G484: =IFERROR(VLOOKUP($C484,Tabla_Documentos[],5,FALSE),"") -> 17850 | H484: =IFERROR(VLOOKUP($C484,Tabla_Documentos[],6,FALSE),"") -> PUBLICIDAD | I484: =IFERROR(VLOOKUP($C484,Tabla_Documentos[],5,FALSE),"") -> 17850 | J484: 45875
C485: 1389 | D485: =IFERROR(VLOOKUP($C485,Tabla_Documentos[],2,FALSE),"") -> 45876 | E485: =IFERROR(VLOOKUP($C485,Tabla_Documentos[],3,FALSE),"") -> 78511870-7 | F485: =IFERROR(VLOOKUP($C485,Tabla_Documentos[],4,FALSE),"") -> EMPRESA DE TRANSPORTE DE PASAJEROS QUILICAL LIMITADA | G485: =IFERROR(VLOOKUP($C485,Tabla_Documentos[],5,FALSE),"") -> 1166200 | H485: =IFERROR(VLOOKUP($C485,Tabla_Documentos[],6,FALSE),"") -> PUBLICIDAD | I485: 250000 | J485: 45940
C486: 1390 | D486: =IFERROR(VLOOKUP($C486,Tabla_Documentos[],2,FALSE),"") -> 45876 | E486: =IFERROR(VLOOKUP($C486,Tabla_Documentos[],3,FALSE),"") -> 76303840-8 | F486: =IFERROR(VLOOKUP($C486,Tabla_Documentos[],4,FALSE),"") -> TRANSPORTES VERASAY SPA | G486: =IFERROR(VLOOKUP($C486,Tabla_Documentos[],5,FALSE),"") -> 416500 | H486: =IFERROR(VLOOKUP($C486,Tabla_Documentos[],6,FALSE),"") -> PUBLICIDAD | I486: =IFERROR(VLOOKUP($C486,Tabla_Documentos[],5,FALSE),"") -> 416500 | J486: 45923
C487: 1391 | D487: =IFERROR(VLOOKUP($C487,Tabla_Documentos[],2,FALSE),"") -> 45876 | E487: =IFERROR(VLOOKUP($C487,Tabla_Documentos[],3,FALSE),"") -> 77758444-8 | F487: =IFERROR(VLOOKUP($C487,Tabla_Documentos[],4,FALSE),"") -> TRANSPORTE DOBLE C SPA | G487: =IFERROR(VLOOKUP($C487,Tabla_Documentos[],5,FALSE),"") -> 416500 | H487: =IFERROR(VLOOKUP($C487,Tabla_Documentos[],6,FALSE),"") -> PUBLICIDAD | I487: =IFERROR(VLOOKUP($C487,Tabla_Documentos[],5,FALSE),"") -> 416500 | J487: 45876
C488: 1392 | D488: =IFERROR(VLOOKUP($C488,Tabla_Documentos[],2,FALSE),"") -> 45877 | E488: =IFERROR(VLOOKUP($C488,Tabla_Documentos[],3,FALSE),"") -> 83714300-4 | F488: =IFERROR(VLOOKUP($C488,Tabla_Documentos[],4,FALSE),"") -> COMPAÑÍA EXPLOTADORA MINERA SAN ANDRES | G488: =IFERROR(VLOOKUP($C488,Tabla_Documentos[],5,FALSE),"") -> 76160 | H488: =IFERROR(VLOOKUP($C488,Tabla_Documentos[],6,FALSE),"") -> BELEN | I488: =IFERROR(VLOOKUP($C488,Tabla_Documentos[],5,FALSE),"") -> 76160 | J488: 45877
C489: 1393 | D489: =IFERROR(VLOOKUP($C489,Tabla_Documentos[],2,FALSE),"") -> 45877 | E489: =IFERROR(VLOOKUP($C489,Tabla_Documentos[],3,FALSE),"") -> 76255245-0 | F489: =IFERROR(VLOOKUP($C489,Tabla_Documentos[],4,FALSE),"") -> SIDESA CHILE S.A. | G489: =IFERROR(VLOOKUP($C489,Tabla_Documentos[],5,FALSE),"") -> 46648 | H489: =IFERROR(VLOOKUP($C489,Tabla_Documentos[],6,FALSE),"") -> BELEN | I489: =IFERROR(VLOOKUP($C489,Tabla_Documentos[],5,FALSE),"") -> 46648 | J489: 45911
C490: 1394 | D490: =IFERROR(VLOOKUP($C490,Tabla_Documentos[],2,FALSE),"") -> 45877 | E490: =IFERROR(VLOOKUP($C490,Tabla_Documentos[],3,FALSE),"") -> 76255245-0 | F490: =IFERROR(VLOOKUP($C490,Tabla_Documentos[],4,FALSE),"") -> SIDESA CHILE S.A. | G490: =IFERROR(VLOOKUP($C490,Tabla_Documentos[],5,FALSE),"") -> 160650 | H490: =IFERROR(VLOOKUP($C490,Tabla_Documentos[],6,FALSE),"") -> PUBLICIDAD | I490: =IFERROR(VLOOKUP($C490,Tabla_Documentos[],5,FALSE),"") -> 160650 | J490: 45908
C491: 1395 | D491: =IFERROR(VLOOKUP($C491,Tabla_Documentos[],2,FALSE),"") -> 45877 | E491: =IFERROR(VLOOKUP($C491,Tabla_Documentos[],3,FALSE),"") -> 76255245-0 | F491: =IFERROR(VLOOKUP($C491,Tabla_Documentos[],4,FALSE),"") -> SIDESA CHILE S.A. | G491: =IFERROR(VLOOKUP($C491,Tabla_Documentos[],5,FALSE),"") -> 267750 | H491: =IFERROR(VLOOKUP($C491,Tabla_Documentos[],6,FALSE),"") -> PUBLICIDAD | I491: =IFERROR(VLOOKUP($C491,Tabla_Documentos[],5,FALSE),"") -> 267750 | J491: 45908
C492: 1396 | D492: =IFERROR(VLOOKUP($C492,Tabla_Documentos[],2,FALSE),"") -> 45880 | E492: =IFERROR(VLOOKUP($C492,Tabla_Documentos[],3,FALSE),"") -> 9051431-8 | F492: =IFERROR(VLOOKUP($C492,Tabla_Documentos[],4,FALSE),"") -> RAMON ANGEL RIQUELME OLIVARES | G492: =IFERROR(VLOOKUP($C492,Tabla_Documentos[],5,FALSE),"") -> 20000 | H492: =IFERROR(VLOOKUP($C492,Tabla_Documentos[],6,FALSE),"") -> PUBLICIDAD | I492: =IFERROR(VLOOKUP($C492,Tabla_Documentos[],5,FALSE),"") -> 20000 | J492: 45880
C493: 1397 | D493: =IFERROR(VLOOKUP($C493,Tabla_Documentos[],2,FALSE),"") -> 45880 | E493: =IFERROR(VLOOKUP($C493,Tabla_Documentos[],3,FALSE),"") -> 77449132-5 | F493: =IFERROR(VLOOKUP($C493,Tabla_Documentos[],4,FALSE),"") -> ALICE IMPORT EXPORT LIMITADA | G493: =IFERROR(VLOOKUP($C493,Tabla_Documentos[],5,FALSE),"") -> 35700 | H493: =IFERROR(VLOOKUP($C493,Tabla_Documentos[],6,FALSE),"") -> PUBLICIDAD | I493: =IFERROR(VLOOKUP($C493,Tabla_Documentos[],5,FALSE),"") -> 35700 | J493: 45880
C494: 1398 | D494: =IFERROR(VLOOKUP($C494,Tabla_Documentos[],2,FALSE),"") -> 45880 | E494: =IFERROR(VLOOKUP($C494,Tabla_Documentos[],3,FALSE),"") -> 77389370-5 | F494: =IFERROR(VLOOKUP($C494,Tabla_Documentos[],4,FALSE),"") -> PROTAB SPA | G494: =IFERROR(VLOOKUP($C494,Tabla_Documentos[],5,FALSE),"") -> 83300 | H494: =IFERROR(VLOOKUP($C494,Tabla_Documentos[],6,FALSE),"") -> PUBLICIDAD | I494: =IFERROR(VLOOKUP($C494,Tabla_Documentos[],5,FALSE),"") -> 83300 | J494: 45880
C495: 1399 | D495: =IFERROR(VLOOKUP($C495,Tabla_Documentos[],2,FALSE),"") -> 45881 | E495: =IFERROR(VLOOKUP($C495,Tabla_Documentos[],3,FALSE),"") -> 76366587-9 | F495: =IFERROR(VLOOKUP($C495,Tabla_Documentos[],4,FALSE),"") -> CONSTRUCTORA VGA SPA | G495: =IFERROR(VLOOKUP($C495,Tabla_Documentos[],5,FALSE),"") -> 50000 | H495: =IFERROR(VLOOKUP($C495,Tabla_Documentos[],6,FALSE),"") -> PUBLICIDAD | I495: =IFERROR(VLOOKUP($C495,Tabla_Documentos[],5,FALSE),"") -> 50000 | J495: 45881
C496: 1400 | D496: =IFERROR(VLOOKUP($C496,Tabla_Documentos[],2,FALSE),"") -> 45882 | E496: =IFERROR(VLOOKUP($C496,Tabla_Documentos[],3,FALSE),"") -> 96792430-K | F496: =IFERROR(VLOOKUP($C496,Tabla_Documentos[],4,FALSE),"") -> SODIMAC S.A. | G496: =IFERROR(VLOOKUP($C496,Tabla_Documentos[],5,FALSE),"") -> 1448230 | H496: =IFERROR(VLOOKUP($C496,Tabla_Documentos[],6,FALSE),"") -> BELEN | I496: =IFERROR(VLOOKUP($C496,Tabla_Documentos[],5,FALSE),"") -> 1448230 | J496: 45912
C497: 1401 | D497: =IFERROR(VLOOKUP($C497,Tabla_Documentos[],2,FALSE),"") -> 45882 | E497: =IFERROR(VLOOKUP($C497,Tabla_Documentos[],3,FALSE),"") -> 76187388-1 | F497: =IFERROR(VLOOKUP($C497,Tabla_Documentos[],4,FALSE),"") -> NORTENERGY SOCIEDAD POR ACCIONES SPA | G497: =IFERROR(VLOOKUP($C497,Tabla_Documentos[],5,FALSE),"") -> 535500 | H497: =IFERROR(VLOOKUP($C497,Tabla_Documentos[],6,FALSE),"") -> PUBLICIDAD | I497: =IFERROR(VLOOKUP($C497,Tabla_Documentos[],5,FALSE),"") -> 535500 | J497: 45903
... C770: 1687 | D770: =IFERROR(VLOOKUP($C770,Tabla_Documentos[],2,FALSE),"") -> 46021 | E770: =IFERROR(VLOOKUP($C770,Tabla_Documentos[],3,FALSE),"") -> 76864812-3 | F770: =IFERROR(VLOOKUP($C770,Tabla_Documentos[],4,FALSE),"") -> INVERSIONES SANTA LUISA LIMITADA | G770: =IFERROR(VLOOKUP($C770,Tabla_Documentos[],5,FALSE),"") -> 23800 | H770: =IFERROR(VLOOKUP($C770,Tabla_Documentos[],6,FALSE),"") -> PUBLICIDAD | I770: =IFERROR(VLOOKUP($C770,Tabla_Documentos[],5,FALSE),"") -> 23800 | J770: 46021
C771: 1688 | D771: =IFERROR(VLOOKUP($C771,Tabla_Documentos[],2,FALSE),"") -> 46022 | E771: =IFERROR(VLOOKUP($C771,Tabla_Documentos[],3,FALSE),"") -> 77382153-4 | F771: =IFERROR(VLOOKUP($C771,Tabla_Documentos[],4,FALSE),"") -> AUCAN LOGISTIC SPA | G771: =IFERROR(VLOOKUP($C771,Tabla_Documentos[],5,FALSE),"") -> 5429970 | H771: =IFERROR(VLOOKUP($C771,Tabla_Documentos[],6,FALSE),"") -> PUBLICIDAD | I771: 1000000 | J771: 46027
C772: 1689 | D772: =IFERROR(VLOOKUP($C772,Tabla_Documentos[],2,FALSE),"") -> 46022 | E772: =IFERROR(VLOOKUP($C772,Tabla_Documentos[],3,FALSE),"") -> 77680509-2 | F772: =IFERROR(VLOOKUP($C772,Tabla_Documentos[],4,FALSE),"") -> RCR TÃCTICAL TECHNOLOGY SUPPORT SPA | G772: =IFERROR(VLOOKUP($C772,Tabla_Documentos[],5,FALSE),"") -> 3000000 | H772: =IFERROR(VLOOKUP($C772,Tabla_Documentos[],6,FALSE),"") -> PUBLICIDAD | I772: =IFERROR(VLOOKUP($C772,Tabla_Documentos[],5,FALSE),"") -> 3000000 | J772: 46022
C773: 1690 | D773: =IFERROR(VLOOKUP($C773,Tabla_Documentos[],2,FALSE),"") -> 46022 | E773: =IFERROR(VLOOKUP($C773,Tabla_Documentos[],3,FALSE),"") -> 77880032-2 | F773: =IFERROR(VLOOKUP($C773,Tabla_Documentos[],4,FALSE),"") -> OPTICAS JOVAL SPA | G773: =IFERROR(VLOOKUP($C773,Tabla_Documentos[],5,FALSE),"") -> 2000000 | H773: =IFERROR(VLOOKUP($C773,Tabla_Documentos[],6,FALSE),"") -> PUBLICIDAD | I773: =IFERROR(VLOOKUP($C773,Tabla_Documentos[],5,FALSE),"") -> 2000000 | J773: 46022
C774: 1691 | D774: =IFERROR(VLOOKUP($C774,Tabla_Documentos[],2,FALSE),"") -> 46024 | E774: =IFERROR(VLOOKUP($C774,Tabla_Documentos[],3,FALSE),"") -> 77461548-2 | F774: =IFERROR(VLOOKUP($C774,Tabla_Documentos[],4,FALSE),"") -> TRANSPORTES KIMSA, SERVICIOS DISTRIBUCION SPA | G774: =IFERROR(VLOOKUP($C774,Tabla_Documentos[],5,FALSE),"") -> 47600 | H774: =IFERROR(VLOOKUP($C774,Tabla_Documentos[],6,FALSE),"") -> PUBLICIDAD | I774: =IFERROR(VLOOKUP($C774,Tabla_Documentos[],5,FALSE),"") -> 47600 | J774: 46024
C775: 1693 | D775: =IFERROR(VLOOKUP($C775,Tabla_Documentos[],2,FALSE),"") -> 46027 | E775: =IFERROR(VLOOKUP($C775,Tabla_Documentos[],3,FALSE),"") -> 77840923-2 | F775: =IFERROR(VLOOKUP($C775,Tabla_Documentos[],4,FALSE),"") -> INGENIERIA GACITUA SPA | G775: =IFERROR(VLOOKUP($C775,Tabla_Documentos[],5,FALSE),"") -> 433160 | H775: =IFERROR(VLOOKUP($C775,Tabla_Documentos[],6,FALSE),"") -> PUBLICIDAD | I775: =IFERROR(VLOOKUP($C775,Tabla_Documentos[],5,FALSE),"") -> 433160 | J775: 46027
C776: 1694 | D776: =IFERROR(VLOOKUP($C776,Tabla_Documentos[],2,FALSE),"") -> 46027 | E776: =IFERROR(VLOOKUP($C776,Tabla_Documentos[],3,FALSE),"") -> 77288671-3 | F776: =IFERROR(VLOOKUP($C776,Tabla_Documentos[],4,FALSE),"") -> TRANSPORTES GALLARDO LIMITADA | G776: =IFERROR(VLOOKUP($C776,Tabla_Documentos[],5,FALSE),"") -> 35700 | H776: =IFERROR(VLOOKUP($C776,Tabla_Documentos[],6,FALSE),"") -> PUBLICIDAD | I776: =IFERROR(VLOOKUP($C776,Tabla_Documentos[],5,FALSE),"") -> 35700 | J776: 46027
C777: 1695 | D777: =IFERROR(VLOOKUP($C777,Tabla_Documentos[],2,FALSE),"") -> 46028 | E777: =IFERROR(VLOOKUP($C777,Tabla_Documentos[],3,FALSE),"") -> 52003237-1 | F777: =IFERROR(VLOOKUP($C777,Tabla_Documentos[],4,FALSE),"") -> ANAKENA GROUP SPA | G777: =IFERROR(VLOOKUP($C777,Tabla_Documentos[],5,FALSE),"") -> 20000 | H777: =IFERROR(VLOOKUP($C777,Tabla_Documentos[],6,FALSE),"") -> PUBLICIDAD | I777: =IFERROR(VLOOKUP($C777,Tabla_Documentos[],5,FALSE),"") -> 20000 | J777: 46028
C778: 1696 | D778: =IFERROR(VLOOKUP($C778,Tabla_Documentos[],2,FALSE),"") -> 46028 | E778: =IFERROR(VLOOKUP($C778,Tabla_Documentos[],3,FALSE),"") -> 78080199-9 | F778: =IFERROR(VLOOKUP($C778,Tabla_Documentos[],4,FALSE),"") -> LATORRE INGENIERIA SPA | G778: =IFERROR(VLOOKUP($C778,Tabla_Documentos[],5,FALSE),"") -> 90000 | H778: =IFERROR(VLOOKUP($C778,Tabla_Documentos[],6,FALSE),"") -> PUBLICIDAD | I778: =IFERROR(VLOOKUP($C778,Tabla_Documentos[],5,FALSE),"") -> 90000 | J778: 46028
...

Sheet CALCULOS
B2: Estado pago | C2: Documentos | D2: Importe | E2: % Docs | G2: Estado pago | H2: Documentos | I2: Importe
B3: No vencido | C3: =COUNTIF(Tabla_Documentos[ESTADO DE PAGO],B3) -> 11 | D3: =SUMIF(Tabla_Documentos[ESTADO DE PAGO],B3,Tabla_Documentos[IMPORTE POR COBRAR]) -> 3813236 | E3: =IFERROR(C3/$C$5,"") -> 0.14864865 | G3: No vencido | H3: =IFERROR(GETPIVOTDATA("NRO DE DOCUMENTOS",#REF!,"ESTADO DE PAGO","No vencido"),0) -> 0 | I3: =IFERROR(GETPIVOTDATA("IMPORTE POR COBRAR ",#REF!,"ESTADO DE PAGO","No vencido"),0) -> 0
B4: Vencido | C4: =COUNTIF(Tabla_Documentos[ESTADO DE PAGO],B4) -> 63 | D4: =SUMIF(Tabla_Documentos[ESTADO DE PAGO],B4,Tabla_Documentos[IMPORTE POR COBRAR]) -> 20727204 | E4: =IFERROR(C4/$C$5,"") -> 0.85135135 | G4: Vencido | H4: =IFERROR(GETPIVOTDATA("NRO DE DOCUMENTOS",#REF!,"ESTADO DE PAGO","Vencido"),0) -> 0 | I4: =IFERROR(GETPIVOTDATA("IMPORTE POR COBRAR ",#REF!,"ESTADO DE PAGO","Vencido"),0) -> 0
C5: =C3+C4 -> 74 | D5: =D3+D4 -> 24540440 | E5: =E3+E4 -> 1 | H5: =H3+H4 -> 0 | I5: =I3+I4 -> 0
